<mujoco model="walled arena">
  <default>
    <default class="/"/>
    <default class="pointmass/"/>
  </default>
  <asset>
    <texture name="grid" type="2d" builtin="checker" rgb1="0.10000000000000001 0.20000000000000001 0.29999999999999999" rgb2="0.20000000000000001 0.29999999999999999 0.40000000000000002" mark="edge" markrgb="0.20000000000000001 0.29999999999999999 0.40000000000000002" width="300" height="300"/>
    <material name="grid" class="/" texture="grid" texrepeat="1 1" texuniform="true" reflectance="0"/>
    <material name="decoration" class="/" rgba="0.29999999999999999 0.5 0.69999999999999996 1"/>
  </asset>
  <worldbody>
    <light name="light0" class="/" pos="0.25 0.25 1"/>
    <light name="light1" class="/" pos="-0.25 -0.25 1"/>
    <camera name="fixed" class="/" pos="0 0 0.75" quat="1 0 0 0"/>
    <geom name="ground" class="/" type="plane" size="0.5 0.5 0.10000000000000001" material="grid" pos="0 0 0"/>
    <geom name="wall_x" class="/" type="plane" size="0.02 0.5 0.02" material="decoration" pos="-0.5 0 0.02" zaxis="1 0 0"/>
    <geom name="wall_y" class="/" type="plane" size="0.5 0.02 0.02" material="decoration" pos="0 -0.5 0.02" zaxis="0 1 0"/>
    <geom name="wall_neg_x" class="/" type="plane" size="0.02 0.5 0.02" material="decoration" pos="0.5 0 0.02" zaxis="-1 0 0"/>
    <geom name="wall_neg_y" class="/" type="plane" size="0.5 0.02 0.02" material="decoration" pos="0 0.5 0.02" zaxis="0 -1 0"/>
    <body name="pointmass_mocap" mocap="true" pos="0 0 0">
      <site name="//unnamed_site_0" class="/" type="sphere" size="0.0050000000000000001"/>
    </body>
    <body name="pointmass/">
      <body name="pointmass/pointmass_body" pos="0 0 0.02">
        <geom name="pointmass//unnamed_geom_0" class="pointmass/" type="sphere" size="0.02" rgba="255 0 0 0.5" mass="0.10000000000000001"/>
        <joint name="pointmass/pointmass_x" class="pointmass/" type="slide" axis="1 0 0"/>
        <joint name="pointmass/pointmass_y" class="pointmass/" type="slide" axis="0 1 0"/>
      </body>
    </body>
    <site name="target" class="/" type="box" rgba="0 255 0 1" size="0.01 0.01 0.01" pos="0.25 0.25 0.01"/>
  </worldbody>
  <equality>
    <weld name="mocap_to_mass_weld" class="/" body1="pointmass_mocap" body2="pointmass/pointmass_body"/>
  </equality>
</mujoco>
